<?xml version="1.0" encoding="UTF-8"?>
<!-- Generated by org.testng.reporters.JUnitReportReporter -->
<testsuite skipped="0" hostname="DESKTOP-CRHCDT9" name="Assertion.SoftAssertDemo" tests="2" failures="2" timestamp="25 Nov 2017 07:56:37 GMT" time="0.024" errors="0">
  <testcase name="testHardAssert" time="0.016" classname="Assertion.SoftAssertDemo">
    <failure type="java.lang.AssertionError" message="expected [13] but found [12]">
      <![CDATA[java.lang.AssertionError: expected [13] but found [12]
	at org.testng.Assert.fail(Assert.java:93)
	at org.testng.Assert.failNotEquals(Assert.java:512)
	at org.testng.Assert.assertEqualsImpl(Assert.java:134)
	at org.testng.Assert.assertEquals(Assert.java:115)
	at org.testng.Assert.assertEquals(Assert.java:388)
	at org.testng.Assert.assertEquals(Assert.java:398)
	at Assertion.SoftAssertDemo.testHardAssert(SoftAssertDemo.java:19)
	at sun.reflect.NativeMethodAccessorImpl.invoke0(Native Method)
	at sun.reflect.NativeMethodAccessorImpl.invoke(Unknown Source)
	at sun.reflect.DelegatingMethodAccessorImpl.invoke(Unknown Source)
	at java.lang.reflect.Method.invoke(Unknown Source)
	at org.testng.internal.MethodInvocationHelper.invokeMethod(MethodInvocationHelper.java:108)
	at org.testng.internal.Invoker.invokeMethod(Invoker.java:669)
	at org.testng.internal.Invoker.invokeTestMethod(Invoker.java:877)
	at org.testng.internal.Invoker.invokeTestMethods(Invoker.java:1201)
	at org.testng.internal.TestMethodWorker.invokeTestMethods(TestMethodWorker.java:125)
	at org.testng.internal.TestMethodWorker.run(TestMethodWorker.java:109)
	at org.testng.TestRunner.privateRun(TestRunner.java:776)
	at org.testng.TestRunner.run(TestRunner.java:634)
	at org.testng.SuiteRunner.runTest(SuiteRunner.java:425)
	at org.testng.SuiteRunner.runSequentially(SuiteRunner.java:420)
	at org.testng.SuiteRunner.privateRun(SuiteRunner.java:385)
	at org.testng.SuiteRunner.run(SuiteRunner.java:334)
	at org.testng.SuiteRunnerWorker.runSuite(SuiteRunnerWorker.java:52)
	at org.testng.SuiteRunnerWorker.run(SuiteRunnerWorker.java:86)
	at org.testng.TestNG.runSuitesSequentially(TestNG.java:1318)
	at org.testng.TestNG.runSuitesLocally(TestNG.java:1243)
	at org.testng.TestNG.runSuites(TestNG.java:1161)
	at org.testng.TestNG.run(TestNG.java:1129)
	at org.testng.remote.AbstractRemoteTestNG.run(AbstractRemoteTestNG.java:114)
	at org.testng.remote.RemoteTestNG.initAndRun(RemoteTestNG.java:251)
	at org.testng.remote.RemoteTestNG.main(RemoteTestNG.java:77)
]]>
    </failure>
  </testcase> <!-- testHardAssert -->
  <testcase name="testSoftAssert" time="0.008" classname="Assertion.SoftAssertDemo">
    <failure type="java.lang.AssertionError" message="The following asserts failed:
	Count doesn&#039;t match expected [13] but found [12]">
      <![CDATA[java.lang.AssertionError: The following asserts failed:
	Count doesn't match expected [13] but found [12]
	at org.testng.asserts.SoftAssert.assertAll(SoftAssert.java:43)
	at Assertion.SoftAssertDemo.testSoftAssert(SoftAssertDemo.java:14)
	at sun.reflect.NativeMethodAccessorImpl.invoke0(Native Method)
	at sun.reflect.NativeMethodAccessorImpl.invoke(Unknown Source)
	at sun.reflect.DelegatingMethodAccessorImpl.invoke(Unknown Source)
	at java.lang.reflect.Method.invoke(Unknown Source)
	at org.testng.internal.MethodInvocationHelper.invokeMethod(MethodInvocationHelper.java:108)
	at org.testng.internal.Invoker.invokeMethod(Invoker.java:669)
	at org.testng.internal.Invoker.invokeTestMethod(Invoker.java:877)
	at org.testng.internal.Invoker.invokeTestMethods(Invoker.java:1201)
	at org.testng.internal.TestMethodWorker.invokeTestMethods(TestMethodWorker.java:125)
	at org.testng.internal.TestMethodWorker.run(TestMethodWorker.java:109)
	at org.testng.TestRunner.privateRun(TestRunner.java:776)
	at org.testng.TestRunner.run(TestRunner.java:634)
	at org.testng.SuiteRunner.runTest(SuiteRunner.java:425)
	at org.testng.SuiteRunner.runSequentially(SuiteRunner.java:420)
	at org.testng.SuiteRunner.privateRun(SuiteRunner.java:385)
	at org.testng.SuiteRunner.run(SuiteRunner.java:334)
	at org.testng.SuiteRunnerWorker.runSuite(SuiteRunnerWorker.java:52)
	at org.testng.SuiteRunnerWorker.run(SuiteRunnerWorker.java:86)
	at org.testng.TestNG.runSuitesSequentially(TestNG.java:1318)
	at org.testng.TestNG.runSuitesLocally(TestNG.java:1243)
	at org.testng.TestNG.runSuites(TestNG.java:1161)
	at org.testng.TestNG.run(TestNG.java:1129)
	at org.testng.remote.AbstractRemoteTestNG.run(AbstractRemoteTestNG.java:114)
	at org.testng.remote.RemoteTestNG.initAndRun(RemoteTestNG.java:251)
	at org.testng.remote.RemoteTestNG.main(RemoteTestNG.java:77)
]]>
    </failure>
  </testcase> <!-- testSoftAssert -->
</testsuite> <!-- Assertion.SoftAssertDemo -->
